Workbook

Sheet Сентябрь25
A2: Остаток | D2: Выручка | E2: Терминал | G2: Инкассация | I2: В кассе
A3: 0 | D3: =D44 -> 0 | E3: =E44 -> 0 | G3: =G44 -> 0 | I3: 0
A5: г. Москва
A7: 2025 | B7: Сентябрь
A8: раб/дн | B8: =NETWORKDAYS(A14,A43) -> 22
A10: ТМ | B10: Смола
A12: Дата | B12: Выручка | C12: Возврат | D12: Выручка фактическая | E12: Оплачено по картам | F12: Количество чеков | G12: Инкассация | H12: Сумма выр наличные | I12: Остаток в кассе | J12: Продавец 1 | K12: Время прихода | L12: Время ухода | M12: Продавец 2 | N12: Время прихода | O12: Время ухода
I13: =A3 -> 0
A14: 45901 | D14: =B14-C14 -> 0 | H14: =D14-E14 -> 0 | I14: =I13+H14-G14 -> 0
A15: 45902 | D15: =B15-C15 -> 0 | H15: =D15-E15 -> 0 | I15: =I14+H15-G15 -> 0
A16: 45903 | D16: =B16-C16 -> 0 | H16: =D16-E16 -> 0 | I16: =I15+H16-G16 -> 0
A17: 45904 | D17: =B17-C17 -> 0 | H17: =D17-E17 -> 0 | I17: =I16+H17-G17 -> 0
A18: 45905 | D18: =B18-C18 -> 0 | H18: =D18-E18 -> 0 | I18: =I17+H18-G18 -> 0
A19: 45906 | D19: =B19-C19 -> 0 | H19: =D19-E19 -> 0 | I19: =I18+H19-G19 -> 0
A20: 45907 | D20: =B20-C20 -> 0 | H20: =D20-E20 -> 0 | I20: =I19+H20-G20 -> 0
A21: 45908 | D21: =B21-C21 -> 0 | H21: =D21-E21 -> 0 | I21: =I20+H21-G21 -> 0
A22: 45909 | D22: =B22-C22 -> 0 | H22: =D22-E22 -> 0 | I22: =I21+H22-G22 -> 0
A23: 45910 | D23: =B23-C23 -> 0 | H23: =D23-E23 -> 0 | I23: =I22+H23-G23 -> 0
A24: 45911 | D24: =B24-C24 -> 0 | H24: =D24-E24 -> 0 | I24: =I23+H24-G24 -> 0
A25: 45912 | D25: =B25-C25 -> 0 | H25: =D25-E25 -> 0 | I25: =I24+H25-G25 -> 0
... A43: 45930 | D43: =B43-C43 -> 0 | H43: =D43-E43 -> 0 | I43: =I42+H43-G43 -> 0
B44: =SUM(B14:B43) -> 0 | C44: =SUM(C14:C43) -> 0 | D44: =SUM(D14:D43) -> 0 | E44: =SUM(E14:E43) -> 0 | F44: =SUM(F14:F43) -> 0 | G44: =SUM(G14:G43) -> 0
C46: Кол-во дней | D46: =B8 -> 22
C47: ср. выручка | D47: =D44/D46 -> 0
C48: ср. чек | D48: =B44/F44 -> #DIV/0!

Sheet Октябрь25
A2: Остаток | D2: Выручка | E2: Терминал | G2: Инкассация | I2: В кассе
A3: =Сентябрь25!I3 -> 0 | D3: =D45 -> 312735 | E3: =E45 -> 300324 | G3: =G45 -> 8500 | I3: =I44 -> 3911
A5: г. Москва
A7: 2025 | B7: Октябрь
A8: раб/дн | B8: =NETWORKDAYS(A14,A44) -> 23
A10: ТМ | B10: =Сентябрь25!B10 -> Смола
A12: Дата | B12: Выручка | C12: Возврат | D12: Выручка фактическая | E12: Оплачено по картам | F12: Количество чеков | G12: Инкассация | H12: Сумма выр наличные | I12: Остаток в кассе | J12: Продавец 1 | K12: Время прихода | L12: Время ухода | M12: Продавец 2 | N12: Время прихода | O12: Время ухода
I13: =A3 -> 0
A14: 45931 | D14: =B14-C14 -> 0 | H14: =D14-E14 -> 0 | I14: =I13+H14-G14 -> 0
A15: 45932 | D15: =B15-C15 -> 0 | H15: =D15-E15 -> 0 | I15: =I14+H15-G15 -> 0
A16: 45933 | D16: =B16-C16 -> 0 | H16: =D16-E16 -> 0 | I16: =I15+H16-G16 -> 0 | J16: генералка
A17: 45934 | D17: =B17-C17 -> 0 | H17: =D17-E17 -> 0 | I17: =I16+H17-G17 -> 0
A18: 45935 | D18: =B18-C18 -> 0 | H18: =D18-E18 -> 0 | I18: =I17+H18-G18 -> 0
A19: 45936 | D19: =B19-C19 -> 0 | H19: =D19-E19 -> 0 | I19: =I18+H19-G19 -> 0 | J19: растановка
A20: 45937 | B20: 12533 | D20: =B20-C20 -> 12533 | E20: 12440 | F20: 70 | H20: =D20-E20 -> 93 | I20: =I19+H20-G20 -> 93 | J20: Мария | K20: 0.33333333 | L20: 0.79166667 | M20: Таня | N20: 8:00 | O20: 19:00
A21: 45938 | B21: 13418 | D21: =B21-C21 -> 13418 | E21: 13418 | F21: 86 | H21: =D21-E21 -> 0 | I21: =I20+H21-G21 -> 93 | J21: Мария | K21: 0.33333333 | L21: 0.79166667 | M21: Таня | N21: 8:00 | O21: 19:00
A22: 45939 | B22: 15721 | D22: =B22-C22 -> 15721 | E22: 15244 | F22: 76 | H22: =D22-E22 -> 477 | I22: =I21+H22-G22 -> 570 | J22: Таня | K22: 0.33333333 | L22: 0.79166667
A23: 45940 | B23: 17586 | D23: =B23-C23 -> 17586 | E23: 17298 | F23: 75 | G23: 500 | H23: =D23-E23 -> 288 | I23: =I22+H23-G23 -> 358 | J23: Таня | K23: 0.33333333 | L23: 0.79166667
A24: 45941 | D24: =B24-C24 -> 0 | H24: =D24-E24 -> 0 | I24: =I23+H24-G24 -> 358
A25: 45942 | D25: =B25-C25 -> 0 | H25: =D25-E25 -> 0 | I25: =I24+H25-G25 -> 358
A26: 45943 | B26: 15585 | D26: =B26-C26 -> 15585 | E26: 15005 | F26: 68 | H26: =D26-E26 -> 580 | I26: =I25+H26-G26 -> 938 | J26: Таня | K26: 0.33333333 | L26: 0.79166667
A27: 45944 | B27: 18747 | D27: =B27-C27 -> 18747 | E27: 17142 | F27: 82 | H27: =D27-E27 -> 1605 | I27: =I26+H27-G27 -> 2543 | J27: Таня | K27: 0.33333333 | L27: 0.79166667
A28: 45945 | B28: 16341 | D28: =B28-C28 -> 16341 | E28: 15613 | F28: 83 | H28: =D28-E28 -> 728 | I28: =I27+H28-G28 -> 3271 | J28: Таня | K28: 0.33333333 | L28: 0.79166667
A29: 45946 | B29: 16315 | D29: =B29-C29 -> 16315 | E29: 15386 | F29: 81 | H29: =D29-E29 -> 929 | I29: =I28+H29-G29 -> 4200 | J29: Таня | K29: 0.33333333 | L29: 0.79166667
A30: 45947 | B30: 14418 | D30: =B30-C30 -> 14418 | E30: 13045 | F30: 71 | H30: =D30-E30 -> 1373 | I30: =I29+H30-G30 -> 5573 | J30: Таня | K30: 0.33333333 | L30: 0.79166667
A31: 45948 | D31: =B31-C31 -> 0 | H31: =D31-E31 -> 0 | I31: =I30+H31-G31 -> 5573
A32: 45949 | D32: =B32-C32 -> 0 | H32: =D32-E32 -> 0 | I32: =I31+H32-G32 -> 5573
A33: 45950 | B33: 14436 | D33: =B33-C33 -> 14436 | E33: 13282 | F33: 64 | H33: =D33-E33 -> 1154 | I33: =I32+H33-G33 -> 6727 | J33: Таня | K33: 0.33333333 | L33: 0.79166667
A34: 45951 | B34: 14929 | D34: =B34-C34 -> 14929 | E34: 13856 | F34: 71 | H34: =D34-E34 -> 1073 | I34: =I33+H34-G34 -> 7800 | J34: Таня | K34: 0.33333333 | L34: 0.79166667
A35: 45952 | B35: 14994 | D35: =B35-C35 -> 14994 | E35: 14709 | F35: 89 | H35: =D35-E35 -> 285 | I35: =I34+H35-G35 -> 8085 | J35: Таня | K35: 0.33333333 | L35: 0.79166667
A36: 45953 | B36: 17062 | D36: =B36-C36 -> 17062 | E36: 16396 | F36: 81 | H36: =D36-E36 -> 666 | I36: =I35+H36-G36 -> 8751 | J36: Таня | K36: 0.33333333 | L36: 0.79166667
A37: 45954 | B37: 16742 | D37: =B37-C37 -> 16742 | E37: 15748 | F37: 84 | H37: =D37-E37 -> 994 | I37: =I36+H37-G37 -> 9745 | J37: Таня | K37: 0.33333333 | L37: 0.79166667
A38: 45955 | D38: =B38-C38 -> 0 | H38: =D38-E38 -> 0 | I38: =I37+H38-G38 -> 9745
A39: 45956 | D39: =B39-C39 -> 0 | H39: =D39-E39 -> 0 | I39: =I38+H39-G39 -> 9745
A40: 45957 | B40: 17906 | D40: =B40-C40 -> 17906 | E40: 17906 | F40: 74 | H40: =D40-E40 -> 0 | I40: =I39+H40-G40 -> 9745 | J40: Таня | K40: 0.33333333 | L40: 0.79166667
A41: 45958 | B41: 17147 | D41: =B41-C41 -> 17147 | E41: 16578 | F41: 83 | H41: =D41-E41 -> 569 | I41: =I40+H41-G41 -> 10314 | J41: Таня | K41: 0.33333333 | L41: 0.79166667
A42: 45959 | B42: 19015 | D42: =B42-C42 -> 19015 | E42: 18314 | F42: 91 | H42: =D42-E42 -> 701 | I42: =I41+H42-G42 -> 11015 | J42: Таня | K42: 0.33333333 | L42: 0.79166667
A43: 45960 | B43: 20937 | D43: =B43-C43 -> 20937 | E43: 20554 | F43: 102 | G43: 8000 | H43: =D43-E43 -> 383 | I43: =I42+H43-G43 -> 3398 | J43: Таня | K43: 0.33333333 | L43: 0.79166667
A44: 45961 | B44: 18903 | D44: =B44-C44 -> 18903 | E44: 18390 | F44: 94 | H44: =D44-E44 -> 513 | I44: =I43+H44-G44 -> 3911 | J44: Таня | K44: 0.33333333 | L44: 0.79166667
B45: =SUM(B14:B44) -> 312735 | C45: =SUM(C14:C44) -> 0 | D45: =SUM(D14:D44) -> 312735 | E45: =SUM(E14:E44) -> 300324 | F45: =SUM(F14:F44) -> 1525 | G45: =SUM(G14:G44) -> 8500
...

Sheet Ноябрь25
A2: Остаток | D2: Выручка | E2: Терминал | G2: Инкассация | I2: В кассе
A3: =Октябрь25!I3 -> 3911 | D3: =D44 -> 338983 | E3: =E44 -> 313018 | G3: =G44 -> 15000 | I3: =I43 -> 14876
A5: г. Москва
A7: 2025 | B7: Ноябрь
A8: раб/дн | B8: =NETWORKDAYS(A14,A43,A15:A16) -> 19
A10: ТМ | B10: =Октябрь25!B10 -> Смола
A12: Дата | B12: Выручка | C12: Возврат | D12: Выручка фактическая | E12: Оплачено по картам | F12: Количество чеков | G12: Инкассация | H12: Сумма выр наличные | I12: Остаток в кассе | J12: Продавец 1 | K12: Время прихода | L12: Время ухода | M12: Продавец 2 | N12: Время прихода | O12: Время ухода
I13: =A3 -> 3911
A14: 45962 | B14: 12188 | D14: =B14-C14 -> 12188 | E14: 11849 | F14: 67 | H14: =D14-E14 -> 339 | I14: =I13+H14-G14 -> 4250 | J14: Таня
A15: 45963 | D15: =B15-C15 -> 0 | H15: =D15-E15 -> 0 | I15: =I14+H15-G15 -> 4250
A16: 45964 | D16: =B16-C16 -> 0 | H16: =D16-E16 -> 0 | I16: =I15+H16-G16 -> 4250
A17: 45965 | D17: =B17-C17 -> 0 | H17: =D17-E17 -> 0 | I17: =I16+H17-G17 -> 4250
A18: 45966 | B18: 14344 | D18: =B18-C18 -> 14344 | E18: 13096 | F18: 73 | H18: =D18-E18 -> 1248 | I18: =I17+H18-G18 -> 5498 | J18: Таня
A19: 45967 | B19: 12194 | D19: =B19-C19 -> 12194 | E19: 11391 | F19: 68 | H19: =D19-E19 -> 803 | I19: =I18+H19-G19 -> 6301 | J19: Маша
A20: 45968 | B20: 18036 | D20: =B20-C20 -> 18036 | E20: 14834 | F20: 82 | G20: 5000 | H20: =D20-E20 -> 3202 | I20: =I19+H20-G20 -> 4503 | J20: Таня
A21: 45969 | D21: =B21-C21 -> 0 | H21: =D21-E21 -> 0 | I21: =I20+H21-G21 -> 4503
A22: 45970 | D22: =B22-C22 -> 0 | H22: =D22-E22 -> 0 | I22: =I21+H22-G22 -> 4503
A23: 45971 | B23: 22462 | D23: =B23-C23 -> 22462 | E23: 18501 | F23: 100 | H23: =D23-E23 -> 3961 | I23: =I22+H23-G23 -> 8464 | J23: Мария К
A24: 45972 | B24: 17698 | D24: =B24-C24 -> 17698 | E24: 16410 | F24: 93 | H24: =D24-E24 -> 1288 | I24: =I23+H24-G24 -> 9752 | J24: Машуля
A25: 45973 | B25: 19958 | C25: 72 | D25: =B25-C25 -> 19886 | E25: 18650 | F25: 102 | H25: =D25-E25 -> 1236 | I25: =I24+H25-G25 -> 10988 | J25: Машуля
A26: 45974 | B26: 18907 | D26: =B26-C26 -> 18907 | E26: 18907 | F26: 91 | H26: =D26-E26 -> 0 | I26: =I25+H26-G26 -> 10988 | J26: Мария К
A27: 45975 | B27: 15381 | D27: =B27-C27 -> 15381 | E27: 14480 | F27: 85 | H27: =D27-E27 -> 901 | I27: =I26+H27-G27 -> 11889 | J27: Мария К
A28: 45976 | D28: =B28-C28 -> 0 | H28: =D28-E28 -> 0 | I28: =I27+H28-G28 -> 11889
A29: 45977 | D29: =B29-C29 -> 0 | H29: =D29-E29 -> 0 | I29: =I28+H29-G29 -> 11889
A30: 45978 | B30: 16221 | D30: =B30-C30 -> 16221 | E30: 15044 | F30: 85 | H30: =D30-E30 -> 1177 | I30: =I29+H30-G30 -> 13066 | J30: Таня
A31: 45979 | B31: 19321 | D31: =B31-C31 -> 19321 | E31: 18968 | F31: 105 | H31: =D31-E31 -> 353 | I31: =I30+H31-G31 -> 13419 | J31: Таня
A32: 45980 | B32: 17783 | D32: =B32-C32 -> 17783 | E32: 17783 | F32: 85 | H32: =D32-E32 -> 0 | I32: =I31+H32-G32 -> 13419 | J32: Таня
A33: 45981 | B33: 16326 | D33: =B33-C33 -> 16326 | E33: 15870 | F33: 83 | G33: 10000 | H33: =D33-E33 -> 456 | I33: =I32+H33-G33 -> 3875 | J33: Таня
A34: 45982 | B34: 19657 | D34: =B34-C34 -> 19657 | E34: 16221 | F34: 82 | H34: =D34-E34 -> 3436 | I34: =I33+H34-G34 -> 7311 | J34: Таня
A35: 45983 | D35: =B35-C35 -> 0 | H35: =D35-E35 -> 0 | I35: =I34+H35-G35 -> 7311
A36: 45984 | D36: =B36-C36 -> 0 | H36: =D36-E36 -> 0 | I36: =I35+H36-G36 -> 7311
A37: 45985 | B37: 17684 | D37: =B37-C37 -> 17684 | E37: 15109 | F37: 82 | H37: =D37-E37 -> 2575 | I37: =I36+H37-G37 -> 9886 | J37: Таня
A38: 45986 | B38: 18436 | D38: =B38-C38 -> 18436 | E38: 18436 | F38: 95 | H38: =D38-E38 -> 0 | I38: =I37+H38-G38 -> 9886 | J38: Таня
A39: 45987 | B39: 18262 | D39: =B39-C39 -> 18262 | E39: 16870 | F39: 87 | H39: =D39-E39 -> 1392 | I39: =I38+H39-G39 -> 11278 | J39: Таня
A40: 45988 | B40: 25670 | D40: =B40-C40 -> 25670 | E40: 22609 | F40: 115 | H40: =D40-E40 -> 3061 | I40: =I39+H40-G40 -> 14339 | J40: Таня
A41: 45989 | B41: 18527 | D41: =B41-C41 -> 18527 | E41: 17990 | F41: 97 | H41: =D41-E41 -> 537 | I41: =I40+H41-G41 -> 14876 | J41: Таня
A42: 45990 | D42: =B42-C42 -> 0 | H42: =D42-E42 -> 0 | I42: =I41+H42-G42 -> 14876
A43: 45991 | D43: =B43-C43 -> 0 | H43: =D43-E43 -> 0 | I43: =I42+H43-G43 -> 14876
B44: =SUM(B14:B43) -> 339055 | C44: =SUM(C14:C43) -> 72 | D44: =SUM(D14:D43) -> 338983 | E44: =SUM(E14:E43) -> 313018 | F44: =SUM(F14:F43) -> 1677 | G44: =SUM(G14:G43) -> 15000
C46: Кол-во дней | D46: =B8 -> 19
...

Sheet Декабрь25
A2: Остаток | D2: Выручка | E2: Терминал | G2: Инкассация | I2: В кассе
A3: =Ноябрь25!I3 -> 14876 | D3: =D45 -> 462169 | E3: =E45 -> 431167 | G3: =G45 -> 38264 | I3: =I44 -> 7614
A5: г. Москва
A7: 2025 | B7: Декабрь
A8: раб/дн | B8: =NETWORKDAYS(A14,A44,A44) -> 22
A10: ТМ | B10: =Ноябрь25!B10 -> Смола
A12: Дата | B12: Выручка | C12: Возврат | D12: Выручка фактическая | E12: Оплачено по картам | F12: Количество чеков | G12: Инкассация | H12: Сумма выр наличные | I12: Остаток в кассе | J12: Продавец 1 | K12: Время прихода | L12: Время ухода | M12: Продавец 2 | N12: Время прихода | O12: Время ухода
I13: =A3 -> 14876
A14: 45992 | B14: 23004 | D14: =B14-C14 -> 23004 | E14: 21478 | F14: 104 | H14: =D14-E14 -> 1526 | I14: =I13+H14-G14 -> 16402 | J14: Таня
A15: 45993 | B15: 21755 | D15: =B15-C15 -> 21755 | E15: 20426 | F15: 105 | H15: =D15-E15 -> 1329 | I15: =I14+H15-G15 -> 17731 | J15: Таня
A16: 45994 | B16: 20583 | D16: =B16-C16 -> 20583 | E16: 19849 | F16: 104 | H16: =D16-E16 -> 734 | I16: =I15+H16-G16 -> 18465 | J16: Таня
A17: 45995 | B17: 19325 | D17: =B17-C17 -> 19325 | E17: 16356 | F17: 99 | H17: =D17-E17 -> 2969 | I17: =I16+H17-G17 -> 21434 | J17: Таня
A18: 45996 | B18: 21142 | D18: =B18-C18 -> 21142 | E18: 20141 | F18: 88 | G18: 20000 | H18: =D18-E18 -> 1001 | I18: =I17+H18-G18 -> 2435 | J18: Таня
A19: 45997 | D19: =B19-C19 -> 0 | H19: =D19-E19 -> 0 | I19: =I18+H19-G19 -> 2435
A20: 45998 | D20: =B20-C20 -> 0 | H20: =D20-E20 -> 0 | I20: =I19+H20-G20 -> 2435
A21: 45999 | B21: 15245 | D21: =B21-C21 -> 15245 | E21: 14517 | F21: 84 | H21: =D21-E21 -> 728 | I21: =I20+H21-G21 -> 3163 | J21: Таня
A22: 46000 | B22: 22044 | D22: =B22-C22 -> 22044 | E22: 19150 | F22: 89 | H22: =D22-E22 -> 2894 | I22: =I21+H22-G22 -> 6057 | J22: Таня
A23: 46001 | B23: 22330 | D23: =B23-C23 -> 22330 | E23: 22106 | F23: 103 | H23: =D23-E23 -> 224 | I23: =I22+H23-G23 -> 6281 | J23: Таня
A24: 46002 | B24: 19695 | D24: =B24-C24 -> 19695 | E24: 19448 | F24: 103 | H24: =D24-E24 -> 247 | I24: =I23+H24-G24 -> 6528 | J24: Таня
A25: 46003 | B25: 18540 | D25: =B25-C25 -> 18540 | E25: 17426 | F25: 88 | H25: =D25-E25 -> 1114 | I25: =I24+H25-G25 -> 7642 | J25: Таня
A26: 46004 | D26: =B26-C26 -> 0 | H26: =D26-E26 -> 0 | I26: =I25+H26-G26 -> 7642
A27: 46005 | D27: =B27-C27 -> 0 | H27: =D27-E27 -> 0 | I27: =I26+H27-G27 -> 7642
A28: 46006 | B28: 19727 | D28: =B28-C28 -> 19727 | E28: 16954 | F28: 101 | H28: =D28-E28 -> 2773 | I28: =I27+H28-G28 -> 10415 | J28: Таня
A29: 46007 | B29: 20300 | D29: =B29-C29 -> 20300 | E29: 18946 | F29: 100 | H29: =D29-E29 -> 1354 | I29: =I28+H29-G29 -> 11769 | J29: Таня
A30: 46008 | B30: 21746 | D30: =B30-C30 -> 21746 | E30: 21218 | F30: 99 | G30: 8000 | H30: =D30-E30 -> 528 | I30: =I29+H30-G30 -> 4297 | J30: Таня
A31: 46009 | B31: 24240 | D31: =B31-C31 -> 24240 | E31: 22745 | F31: 115 | H31: =D31-E31 -> 1495 | I31: =I30+H31-G31 -> 5792 | J31: Таня
A32: 46010 | B32: 21718 | D32: =B32-C32 -> 21718 | E32: 20434 | F32: 104 | H32: =D32-E32 -> 1284 | I32: =I31+H32-G32 -> 7076 | J32: Таня
A33: 46011 | D33: =B33-C33 -> 0 | H33: =D33-E33 -> 0 | I33: =I32+H33-G33 -> 7076
A34: 46012 | D34: =B34-C34 -> 0 | H34: =D34-E34 -> 0 | I34: =I33+H34-G34 -> 7076
A35: 46013 | B35: 21005 | D35: =B35-C35 -> 21005 | E35: 18860 | F35: 109 | H35: =D35-E35 -> 2145 | I35: =I34+H35-G35 -> 9221 | J35: Таня
A36: 46014 | B36: 23284 | D36: =B36-C36 -> 23284 | E36: 23214 | F36: 113 | H36: =D36-E36 -> 70 | I36: =I35+H36-G36 -> 9291 | J36: Таня
A37: 46015 | B37: 28919 | D37: =B37-C37 -> 28919 | E37: 26189 | F37: 119 | H37: =D37-E37 -> 2730 | I37: =I36+H37-G37 -> 12021 | J37: Таня
A38: 46016 | B38: 22462 | D38: =B38-C38 -> 22462 | E38: 21458 | F38: 100 | H38: =D38-E38 -> 1004 | I38: =I37+H38-G38 -> 13025 | J38: Таня
A39: 46017 | B39: 19997 | D39: =B39-C39 -> 19997 | E39: 19592 | F39: 97 | G39: 264 | H39: =D39-E39 -> 405 | I39: =I38+H39-G39 -> 13166 | J39: Таня
A40: 46018 | D40: =B40-C40 -> 0 | H40: =D40-E40 -> 0 | I40: =I39+H40-G40 -> 13166
A41: 46019 | D41: =B41-C41 -> 0 | H41: =D41-E41 -> 0 | I41: =I40+H41-G41 -> 13166
A42: 46020 | B42: 21076 | D42: =B42-C42 -> 21076 | E42: 19013 | F42: 80 | G42: 10000 | H42: =D42-E42 -> 2063 | I42: =I41+H42-G42 -> 5229 | J42: Таня
A43: 46021 | B43: 14032 | D43: =B43-C43 -> 14032 | E43: 11647 | F43: 51 | H43: =D43-E43 -> 2385 | I43: =I42+H43-G43 -> 7614 | J43: Таня
A44: 46022 | D44: =B44-C44 -> 0 | H44: =D44-E44 -> 0 | I44: =I43+H44-G44 -> 7614
B45: =SUM(B14:B44) -> 462169 | C45: =SUM(C14:C44) -> 0 | D45: =SUM(D14:D44) -> 462169 | E45: =SUM(E14:E44) -> 431167 | F45: =SUM(F14:F44) -> 2155 | G45: =SUM(G14:G44) -> 38264
...

Sheet Январь26
A2: Остаток | D2: Выручка | E2: Терминал | G2: Инкассация | I2: В кассе
A3: =Декабрь25!I3 -> 7614 | D3: =D45 -> 316314 | E3: =E45 -> 293279 | G3: =G45 -> 17000 | I3: =I44 -> 13649
A5: г. Москва
A7: 2025 | B7: Январь
A8: раб/дн | B8: =NETWORKDAYS(A14,A44,A14:A24) -> 15
A10: ТМ | B10: =Декабрь25!B10 -> Смола
A12: Дата | B12: Выручка | C12: Возврат | D12: Выручка фактическая | E12: Оплачено по картам | F12: Количество чеков | G12: Инкассация | H12: Сумма выр наличные | I12: Остаток в кассе | J12: Продавец 1 | K12: Время прихода | L12: Время ухода | M12: Продавец 2 | N12: Время прихода | O12: Время ухода
I13: =A3 -> 7614
A14: 46023 | D14: =B14-C14 -> 0 | H14: =D14-E14 -> 0 | I14: =I13+H14-G14 -> 7614
A15: 46024 | D15: =B15-C15 -> 0 | H15: =D15-E15 -> 0 | I15: =I14+H15-G15 -> 7614
A16: 46025 | D16: =B16-C16 -> 0 | H16: =D16-E16 -> 0 | I16: =I15+H16-G16 -> 7614
A17: 46026 | D17: =B17-C17 -> 0 | H17: =D17-E17 -> 0 | I17: =I16+H17-G17 -> 7614
A18: 46027 | D18: =B18-C18 -> 0 | H18: =D18-E18 -> 0 | I18: =I17+H18-G18 -> 7614
A19: 46028 | D19: =B19-C19 -> 0 | H19: =D19-E19 -> 0 | I19: =I18+H19-G19 -> 7614
A20: 46029 | D20: =B20-C20 -> 0 | H20: =D20-E20 -> 0 | I20: =I19+H20-G20 -> 7614
A21: 46030 | D21: =B21-C21 -> 0 | H21: =D21-E21 -> 0 | I21: =I20+H21-G21 -> 7614
A22: 46031 | D22: =B22-C22 -> 0 | H22: =D22-E22 -> 0 | I22: =I21+H22-G22 -> 7614
A23: 46032 | D23: =B23-C23 -> 0 | H23: =D23-E23 -> 0 | I23: =I22+H23-G23 -> 7614
A24: 46033 | D24: =B24-C24 -> 0 | H24: =D24-E24 -> 0 | I24: =I23+H24-G24 -> 7614
A25: 46034 | B25: 14962 | D25: =B25-C25 -> 14962 | E25: 14128 | F25: 84 | H25: =D25-E25 -> 834 | I25: =I24+H25-G25 -> 8448 | J25: Майорова
A26: 46035 | B26: 19489 | D26: =B26-C26 -> 19489 | E26: 19027 | F26: 90 | H26: =D26-E26 -> 462 | I26: =I25+H26-G26 -> 8910 | J26: Майорова
A27: 46036 | B27: 24603 | D27: =B27-C27 -> 24603 | E27: 23300 | F27: 110 | H27: =D27-E27 -> 1303 | I27: =I26+H27-G27 -> 10213 | J27: Майорова
A28: 46037 | B28: 20871 | D28: =B28-C28 -> 20871 | E28: 19819 | F28: 102 | H28: =D28-E28 -> 1052 | I28: =I27+H28-G28 -> 11265 | J28: Майорова
A29: 46038 | B29: 23552 | D29: =B29-C29 -> 23552 | E29: 19051 | F29: 104 | H29: =D29-E29 -> 4501 | I29: =I28+H29-G29 -> 15766 | J29: Майорова
A30: 46039 | D30: =B30-C30 -> 0 | H30: =D30-E30 -> 0 | I30: =I29+H30-G30 -> 15766
A31: 46040 | D31: =B31-C31 -> 0 | H31: =D31-E31 -> 0 | I31: =I30+H31-G31 -> 15766
A32: 46041 | B32: 18191 | D32: =B32-C32 -> 18191 | E32: 17173 | F32: 107 | H32: =D32-E32 -> 1018 | I32: =I31+H32-G32 -> 16784 | J32: Майорова
A33: 46042 | B33: 21284 | D33: =B33-C33 -> 21284 | E33: 20315 | F33: 104 | H33: =D33-E33 -> 969 | I33: =I32+H33-G33 -> 17753 | J33: Майорова
A34: 46043 | B34: 19099 | D34: =B34-C34 -> 19099 | E34: 18316 | F34: 100 | H34: =D34-E34 -> 783 | I34: =I33+H34-G34 -> 18536 | J34: Майорова
A35: 46044 | B35: 30715 | D35: =B35-C35 -> 30715 | E35: 22909 | F35: 108 | G35: 17000 | H35: =D35-E35 -> 7806 | I35: =I34+H35-G35 -> 9342 | J35: Майорова
A36: 46045 | B36: 18523 | D36: =B36-C36 -> 18523 | E36: 18523 | F36: 87 | H36: =D36-E36 -> 0 | I36: =I35+H36-G36 -> 9342 | J36: Майорова
A37: 46046 | D37: =B37-C37 -> 0 | H37: =D37-E37 -> 0 | I37: =I36+H37-G37 -> 9342
A38: 46047 | D38: =B38-C38 -> 0 | H38: =D38-E38 -> 0 | I38: =I37+H38-G38 -> 9342
A39: 46048 | B39: 25140 | D39: =B39-C39 -> 25140 | E39: 23872 | F39: 103 | H39: =D39-E39 -> 1268 | I39: =I38+H39-G39 -> 10610 | J39: Майорова
A40: 46049 | B40: 16751 | D40: =B40-C40 -> 16751 | E40: 15610 | F40: 93 | H40: =D40-E40 -> 1141 | I40: =I39+H40-G40 -> 11751 | J40: Майорова
A41: 46050 | B41: 24575 | D41: =B41-C41 -> 24575 | E41: 23363 | F41: 104 | H41: =D41-E41 -> 1212 | I41: =I40+H41-G41 -> 12963 | J41: Майорова
A42: 46051 | B42: 22208 | D42: =B42-C42 -> 22208 | E42: 21780 | F42: 102 | H42: =D42-E42 -> 428 | I42: =I41+H42-G42 -> 13391 | J42: Майорова
A43: 46052 | B43: 16351 | D43: =B43-C43 -> 16351 | E43: 16093 | F43: 83 | H43: =D43-E43 -> 258 | I43: =I42+H43-G43 -> 13649 | J43: Майорова
A44: 46053 | D44: =B44-C44 -> 0 | H44: =D44-E44 -> 0 | I44: =I43+H44-G44 -> 13649
B45: =SUM(B14:B44) -> 316314 | C45: =SUM(C14:C44) -> 0 | D45: =SUM(D14:D44) -> 316314 | E45: =SUM(E14:E44) -> 293279 | F45: =SUM(F14:F44) -> 1481 | G45: =SUM(G14:G44) -> 17000
...

Sheet Февраль26
A2: Остаток | D2: Выручка | E2: Терминал | G2: Инкассация | I2: В кассе
A3: =Январь26!I3 -> 13649 | D3: =D42 -> 434926 | E3: =E42 -> 410708 | G3: =G42 -> 26586 | I3: =I41 -> 11281
A5: г. Москва
A7: 2024 | B7: Февраль
A8: раб/дн | B8: =NETWORKDAYS(A14,A41,A36) -> 19
A10: ТМ | B10: =Январь26!B10 -> Смола
A12: Дата | B12: Выручка | C12: Возврат | D12: Выручка фактическая | E12: Оплачено по картам | F12: Количество чеков | G12: Инкассация | H12: Сумма выр наличные | I12: Остаток в кассе | J12: Продавец 1 | K12: Время прихода | L12: Время ухода | M12: Продавец 2 | N12: Время прихода | O12: Время ухода
I13: =A3 -> 13649
A14: 46054 | D14: =B14-C14 -> 0 | H14: =D14-E14 -> 0 | I14: =I13+H14-G14 -> 13649
A15: 46055 | B15: 28067 | D15: =B15-C15 -> 28067 | E15: 25115 | F15: 110 | H15: =D15-E15 -> 2952 | I15: =I14+H15-G15 -> 16601 | J15: Майорова
A16: 46056 | B16: 20586 | D16: =B16-C16 -> 20586 | E16: 19448 | F16: 99 | H16: =D16-E16 -> 1138 | I16: =I15+H16-G16 -> 17739 | J16: Майорова
A17: 46057 | B17: 26018 | D17: =B17-C17 -> 26018 | E17: 25463 | F17: 104 | G17: 13000 | H17: =D17-E17 -> 555 | I17: =I16+H17-G17 -> 5294 | J17: Майорова
A18: 46058 | B18: 21578 | D18: =B18-C18 -> 21578 | E18: 21107 | F18: 101 | H18: =D18-E18 -> 471 | I18: =I17+H18-G18 -> 5765 | J18: Майорова
A19: 46059 | B19: 20560 | D19: =B19-C19 -> 20560 | E19: 18206 | F19: 83 | H19: =D19-E19 -> 2354 | I19: =I18+H19-G19 -> 8119 | J19: Майорова
A20: 46060 | D20: =B20-C20 -> 0 | H20: =D20-E20 -> 0 | I20: =I19+H20-G20 -> 8119
A21: 46061 | D21: =B21-C21 -> 0 | H21: =D21-E21 -> 0 | I21: =I20+H21-G21 -> 8119
A22: 46062 | B22: 24331 | D22: =B22-C22 -> 24331 | E22: 23750 | F22: 120 | G22: 360 | H22: =D22-E22 -> 581 | I22: =I21+H22-G22 -> 8340 | J22: Майорова
A23: 46063 | B23: 27469 | D23: =B23-C23 -> 27469 | E23: 25879 | F23: 118 | H23: =D23-E23 -> 1590 | I23: =I22+H23-G23 -> 9930 | J23: Майорова
A24: 46064 | B24: 21820 | D24: =B24-C24 -> 21820 | E24: 21260 | F24: 107 | H24: =D24-E24 -> 560 | I24: =I23+H24-G24 -> 10490 | J24: Майорова
A25: 46065 | B25: 19060 | D25: =B25-C25 -> 19060 | E25: 18349 | F25: 100 | H25: =D25-E25 -> 711 | I25: =I24+H25-G25 -> 11201 | J25: Майорова
A26: 46066 | B26: 21265 | D26: =B26-C26 -> 21265 | E26: 18330 | F26: 93 | H26: =D26-E26 -> 2935 | I26: =I25+H26-G26 -> 14136 | J26: Майорова
A27: 46067 | D27: =B27-C27 -> 0 | H27: =D27-E27 -> 0 | I27: =I26+H27-G27 -> 14136
A28: 46068 | D28: =B28-C28 -> 0 | H28: =D28-E28 -> 0 | I28: =I27+H28-G28 -> 14136
A29: 46069 | B29: 18619 | D29: =B29-C29 -> 18619 | E29: 18469 | F29: 98 | H29: =D29-E29 -> 150 | I29: =I28+H29-G29 -> 14286 | J29: Майорова
A30: 46070 | B30: 23343 | D30: =B30-C30 -> 23343 | E30: 23154 | F30: 101 | H30: =D30-E30 -> 189 | I30: =I29+H30-G30 -> 14475 | J30: Майорова
A31: 46071 | B31: 22973 | D31: =B31-C31 -> 22973 | E31: 22580 | F31: 109 | H31: =D31-E31 -> 393 | I31: =I30+H31-G31 -> 14868 | J31: Майорова
A32: 46072 | B32: 27228 | D32: =B32-C32 -> 27228 | E32: 24372 | F32: 114 | G32: 13000 | H32: =D32-E32 -> 2856 | I32: =I31+H32-G32 -> 4724 | J32: Майорова
A33: 46073 | B33: 12555 | D33: =B33-C33 -> 12555 | E33: 11957 | F33: 57 | H33: =D33-E33 -> 598 | I33: =I32+H33-G33 -> 5322 | J33: Мария
A34: 46074 | D34: =B34-C34 -> 0 | H34: =D34-E34 -> 0 | I34: =I33+H34-G34 -> 5322
A35: 46075 | D35: =B35-C35 -> 0 | H35: =D35-E35 -> 0 | I35: =I34+H35-G35 -> 5322
A36: 46076 | D36: =B36-C36 -> 0 | H36: =D36-E36 -> 0 | I36: =I35+H36-G36 -> 5322
A37: 46077 | B37: 21360 | D37: =B37-C37 -> 21360 | E37: 18955 | F37: 95 | H37: =D37-E37 -> 2405 | I37: =I36+H37-G37 -> 7727 | J37: Майорова
A38: 46078 | B38: 27150 | D38: =B38-C38 -> 27150 | E38: 26055 | F38: 131 | H38: =D38-E38 -> 1095 | I38: =I37+H38-G38 -> 8822 | J38: Майорова
A39: 46079 | B39: 24296 | D39: =B39-C39 -> 24296 | E39: 23554 | F39: 112 | G39: 226 | H39: =D39-E39 -> 742 | I39: =I38+H39-G39 -> 9338 | J39: Майорова
A40: 46080 | B40: 26648 | D40: =B40-C40 -> 26648 | E40: 24705 | F40: 113 | H40: =D40-E40 -> 1943 | I40: =I39+H40-G40 -> 11281 | J40: Майорова
A41: 46081 | D41: =B41-C41 -> 0 | H41: =D41-E41 -> 0 | I41: =I40+H41-G41 -> 11281
B42: =SUM(B14:B41) -> 434926 | C42: =SUM(C14:C41) -> 0 | D42: =SUM(D14:D41) -> 434926 | E42: =SUM(E14:E41) -> 410708 | F42: =SUM(F14:F41) -> 1965 | G42: =SUM(G14:G41) -> 26586
C44: Кол-во дней | D44: =B8 -> 19
C45: ср. выручка | D45: =D42/D44 -> 22890.842
C46: ср. чек | D46: =B42/F42 -> 221.33639

Sheet Март26
A2: Остаток | D2: Выручка | E2: Терминал | G2: Инкассация | I2: В кассе
A3: =Февраль26!I3 -> 11281 | D3: =D45 -> 529374 | E3: =E45 -> 492107 | G3: =G45 -> 30000 | I3: =I44 -> 18548
A5: г. Москва
A7: 2025 | B7: Март
A8: раб/дн | B8: =NETWORKDAYS(A14,A44,A22) -> 21
A10: ТМ | B10: =Февраль26!B10 -> Смола
A12: Дата | B12: Выручка | C12: Возврат | D12: Выручка фактическая | E12: Оплачено по картам | F12: Количество чеков | G12: Инкассация | H12: Сумма выр наличные | I12: Остаток в кассе | J12: Продавец 1 | K12: Время прихода | L12: Время ухода | M12: Продавец 2 | N12: Время прихода | O12: Время ухода
I13: =A3 -> 11281
A14: 46082 | D14: =B14-C14 -> 0 | H14: =D14-E14 -> 0 | I14: =I13+H14-G14 -> 11281
A15: 46083 | B15: 26490 | D15: =B15-C15 -> 26490 | E15: 24055 | F15: 96 | H15: =D15-E15 -> 2435 | I15: =I14+H15-G15 -> 13716 | J15: Майорова
A16: 46084 | B16: 23190 | D16: =B16-C16 -> 23190 | E16: 22728 | F16: 112 | G16: 10000 | H16: =D16-E16 -> 462 | I16: =I15+H16-G16 -> 4178 | J16: Майорова
A17: 46085 | B17: 24653 | D17: =B17-C17 -> 24653 | E17: 23861 | F17: 118 | H17: =D17-E17 -> 792 | I17: =I16+H17-G17 -> 4970 | J17: Майорова
A18: 46086 | B18: 24555 | D18: =B18-C18 -> 24555 | E18: 23388 | F18: 116 | H18: =D18-E18 -> 1167 | I18: =I17+H18-G18 -> 6137 | J18: Майорова
A19: 46087 | B19: 22467 | D19: =B19-C19 -> 22467 | E19: 20792 | F19: 88 | H19: =D19-E19 -> 1675 | I19: =I18+H19-G19 -> 7812 | J19: Майорова
A20: 46088 | D20: =B20-C20 -> 0 | H20: =D20-E20 -> 0 | I20: =I19+H20-G20 -> 7812
A21: 46089 | D21: =B21-C21 -> 0 | H21: =D21-E21 -> 0 | I21: =I20+H21-G21 -> 7812
A22: 46090 | D22: =B22-C22 -> 0 | H22: =D22-E22 -> 0 | I22: =I21+H22-G22 -> 7812
A23: 46091 | B23: 26312 | D23: =B23-C23 -> 26312 | E23: 23573 | F23: 113 | H23: =D23-E23 -> 2739 | I23: =I22+H23-G23 -> 10551 | J23: Майорова
A24: 46092 | B24: 25087 | D24: =B24-C24 -> 25087 | E24: 24578 | F24: 124 | H24: =D24-E24 -> 509 | I24: =I23+H24-G24 -> 11060 | J24: Майорова
A25: 46093 | B25: 25283 | D25: =B25-C25 -> 25283 | E25: 23266 | F25: 117 | H25: =D25-E25 -> 2017 | I25: =I24+H25-G25 -> 13077 | J25: Майорова
A26: 46094 | B26: 23928 | D26: =B26-C26 -> 23928 | E26: 23140 | F26: 111 | H26: =D26-E26 -> 788 | I26: =I25+H26-G26 -> 13865 | J26: Майорова
A27: 46095 | D27: =B27-C27 -> 0 | H27: =D27-E27 -> 0 | I27: =I26+H27-G27 -> 13865
A28: 46096 | D28: =B28-C28 -> 0 | H28: =D28-E28 -> 0 | I28: =I27+H28-G28 -> 13865
A29: 46097 | B29: 24762 | D29: =B29-C29 -> 24762 | E29: 23160 | F29: 131 | H29: =D29-E29 -> 1602 | I29: =I28+H29-G29 -> 15467 | J29: Майорова
A30: 46098 | B30: 25931 | D30: =B30-C30 -> 25931 | E30: 25363 | F30: 118 | H30: =D30-E30 -> 568 | I30: =I29+H30-G30 -> 16035 | J30: Майорова
A31: 46099 | B31: 29036 | D31: =B31-C31 -> 29036 | E31: 26096 | F31: 126 | H31: =D31-E31 -> 2940 | I31: =I30+H31-G31 -> 18975 | J31: Майорова
A32: 46100 | B32: 26584 | D32: =B32-C32 -> 26584 | E32: 23034 | F32: 114 | G32: 20000 | H32: =D32-E32 -> 3550 | I32: =I31+H32-G32 -> 2525 | J32: Майорова
A33: 46101 | B33: 26642 | D33: =B33-C33 -> 26642 | E33: 22418 | F33: 127 | H33: =D33-E33 -> 4224 | I33: =I32+H33-G33 -> 6749 | J33: Майорова
A34: 46102 | D34: =B34-C34 -> 0 | H34: =D34-E34 -> 0 | I34: =I33+H34-G34 -> 6749
A35: 46103 | D35: =B35-C35 -> 0 | H35: =D35-E35 -> 0 | I35: =I34+H35-G35 -> 6749
A36: 46104 | B36: 35997 | D36: =B36-C36 -> 35997 | E36: 34772 | F36: 143 | H36: =D36-E36 -> 1225 | I36: =I35+H36-G36 -> 7974 | J36: Майорова
A37: 46105 | B37: 22036 | D37: =B37-C37 -> 22036 | E37: 20849 | F37: 108 | H37: =D37-E37 -> 1187 | I37: =I36+H37-G37 -> 9161 | J37: Майорова
A38: 46106 | B38: 22410 | D38: =B38-C38 -> 22410 | E38: 20910 | F38: 110 | H38: =D38-E38 -> 1500 | I38: =I37+H38-G38 -> 10661 | J38: Майорова
A39: 46107 | B39: 25610 | D39: =B39-C39 -> 25610 | E39: 24270 | F39: 122 | H39: =D39-E39 -> 1340 | I39: =I38+H39-G39 -> 12001 | J39: Майорова
A40: 46108 | B40: 23187 | D40: =B40-C40 -> 23187 | E40: 19505 | F40: 104 | H40: =D40-E40 -> 3682 | I40: =I39+H40-G40 -> 15683 | J40: Майорова
A41: 46109 | D41: =B41-C41 -> 0 | H41: =D41-E41 -> 0 | I41: =I40+H41-G41 -> 15683
A42: 46110 | D42: =B42-C42 -> 0 | H42: =D42-E42 -> 0 | I42: =I41+H42-G42 -> 15683
A43: 46111 | B43: 23833 | D43: =B43-C43 -> 23833 | E43: 22833 | F43: 132 | H43: =D43-E43 -> 1000 | I43: =I42+H43-G43 -> 16683 | J43: Мария К
A44: 46112 | B44: 21381 | D44: =B44-C44 -> 21381 | E44: 19516 | F44: 108 | H44: =D44-E44 -> 1865 | I44: =I43+H44-G44 -> 18548 | J44: Мария К
B45: =SUM(B14:B44) -> 529374 | C45: =SUM(C14:C44) -> 0 | D45: =SUM(D14:D44) -> 529374 | E45: =SUM(E14:E44) -> 492107 | F45: =SUM(F14:F44) -> 2438 | G45: =SUM(G14:G44) -> 30000
...
